Workbook

Sheet Werte
A1: Technology Outlook 2025: Matrix Technologien versus produzierende Industrie
C3: Chemie | D3: Pharma | E3: Elektronik/ Instrumente | F3: Elektrotechnik | G3: Fahrzeug- / Maschinenbau | H3: Druck/Holz/ Papier | I3: Energie/Wasser/ Umwelt | J3: Kunststoffe | K3: Metallverarbeitung | L3: Nahrungsmittel | M3: sonstige Industrie
A4: Industrie 5.0 | B4: Digitale Welt | E4: X | F4: x | G4: X | I4: x | J4: x | K4: X | L4: x | M4: X | N4: =COUNTA(C4:M4) -> 8
A5: IoT | B5: Digitale Welt | C5: x | D5: x | E5: x | F5: x | G5: x | H5: x | I5: x | J5: x | K5: x | L5: x | M5: x | N5: =COUNTA(C5:M5) -> 11
A6: PICs | B6: Digitale Welt | E6: x | F6: x | N6: =COUNTA(C6:M6) -> 2
A7: Quantencomputing | B7: Digitale Welt | N7: =COUNTA(C7:M7) -> 0
A8: Ultrazuverlässige Echtzeitkommunikation | B8: Digitale Welt | C8: x | D8: x | E8: x | I8: x | N8: =COUNTA(C8:M8) -> 4
A9: künstliche Photosynthese | B9: Energie & Umwelt | C9: x | I9: x | N9: =COUNTA(C9:M9) -> 2
A10: Kunststoffrecycling | B10: Energie & Umwelt | C10: x | D10: x | H10: x | I10: x | J10: x | L10: x | M10: x | N10: =COUNTA(C10:M10) -> 7
A11: Mobilitätskonzepte | B11: Energie & Umwelt | E11: x | I11: x | L11: x | N11: =COUNTA(C11:M11) -> 3
A12: Negativemissionstechnologien | B12: Energie & Umwelt | C12: x | D12: x | I12: x | L12: x | M12: x | N12: =COUNTA(C12:M12) -> 5
A13: Phosphorrecycling | B13: Energie & Umwelt | I13: x | L13: x | N13: =COUNTA(C13:M13) -> 2
A14: Synfuels (Präzisionskatalyse) | B14: Energie & Umwelt | C14: x | I14: x | N14: =COUNTA(C14:M14) -> 2
A15: Tiefengeothermie | B15: Energie & Umwelt | I15: x | N15: =COUNTA(C15:M15) -> 1
A16: Wasserstoff | B16: Energie & Umwelt | C16: x | G16: x | I16: x | N16: =COUNTA(C16:M16) -> 3
A17: Erdbeobachtung | B17: Space | G17: x | I17: x | L17: x | N17: =COUNTA(C17:M17) -> 3
A18: 2D-Materialien | B18: Fertigungsprozesse und Materialien | E18: x | F18: x | N18: =COUNTA(C18:M18) -> 2
A19: Bioplastik aus Abfall | B19: Fertigungsprozesse und Materialien | C19: x | I19: x | J19: x | N19: =COUNTA(C19:M19) -> 3
A20: CO2-armer Beton | B20: Fertigungsprozesse und Materialien | C20: x | I20: x | N20: =COUNTA(C20:M20) -> 2
A21: CO2-basierte Kunststoffe | B21: Fertigungsprozesse und Materialien | H21: x | I21: x | N21: =COUNTA(C21:M21) -> 2
A22: Faseroptische Sensoren | B22: Fertigungsprozesse und Materialien | C22: x | D22: x | E22: x | F22: x | G22: x | H22: x | I22: x | J22: x | K22: x | L22: x | M22: x | N22: =COUNTA(C22:M22) -> 11
A23: flexible Batterien | B23: Fertigungsprozesse und Materialien | D23: x | E23: x | F23: x | H23: x | N23: =COUNTA(C23:M23) -> 4
A24: nachhaltige Kleb- und Dichtstoffe | B24: Fertigungsprozesse und Materialien | C24: x | G24: x | H24: x | J24: x | N24: =COUNTA(C24:M24) -> 4
A25: Perovskite | B25: Fertigungsprozesse und Materialien | C25: x | E25: x | F25: x | I25: x | N25: =COUNTA(C25:M25) -> 4
A26: Plasmatechnologien | B26: Fertigungsprozesse und Materialien | C26: x | N26: =COUNTA(C26:M26) -> 1
A27: Photonik auf Diamantbasis | B27: Fertigungsprozesse und Materialien | N27: =COUNTA(C27:M27) -> 0
A28: TIMs | B28: Fertigungsprozesse und Materialien | C28: x | G28: x | N28: =COUNTA(C28:M28) -> 2
A29: Bakteriophagen | B29: Life Sciences | D29: x | I29: x | J29: x | L29: x | N29: =COUNTA(C29:M29) -> 4
A30: Bioinspiration | B30: Life Sciences | C30: x | D30: x | E30: x | F30: x | G30: x | I30: x | J30: x | L30: x | N30: =COUNTA(C30:M30) -> 8
A31: Biokatalyse | B31: Life Sciences | C31: x | D31: x | I31: x | J31: x | L31: x | N31: =COUNTA(C31:M31) -> 5
A32: Human Augmentation | B32: Life Sciences | C32: x | D32: x | E32: x | F32: x | G32: x | N32: =COUNTA(C32:M32) -> 5
A33: mRNA | B33: Life Sciences | C33: x | D33: x | L33: x | N33: =COUNTA(C33:M33) -> 3
A34: personalisierte Ernährung | B34: Life Sciences | L34: x | N34: =COUNTA(C34:M34) -> 1
A35: synthetische Biologie | B35: Life Sciences | C35: x | D35: x | L35: x | N35: =COUNTA(C35:M35) -> 3
C44: Chemie | D44: Pharma | E44: Elektronik/ Instrumente | F44: Elektrotechnik | G44: Fahrzeug- / Maschinenbau | H44: Druck/Holz/ Papier | I44: Energie/Wasser/ Umwelt | J44: Kunststoffe | K44: Metallverarbeitung | L44: Nahrungsmittel | M44: sonstige Industrie
B45: Digitale Welt | C45: =COUNTIFS($B$4:$B$35,$B45,C$4:C$35,"<>") -> 2 | D45: =COUNTIFS($B$4:$B$35,$B45,D$4:D$35,"<>") -> 2 | E45: =COUNTIFS($B$4:$B$35,$B45,E$4:E$35,"<>") -> 4 | F45: =COUNTIFS($B$4:$B$35,$B45,F$4:F$35,"<>") -> 3 | G45: =COUNTIFS($B$4:$B$35,$B45,G$4:G$35,"<>") -> 2 | H45: =COUNTIFS($B$4:$B$35,$B45,H$4:H$35,"<>") -> 1 | I45: =COUNTIFS($B$4:$B$35,$B45,I$4:I$35,"<>") -> 3 | J45: =COUNTIFS($B$4:$B$35,$B45,J$4:J$35,"<>") -> 2 | ... M45: =COUNTIFS($B$4:$B$35,$B45,M$4:M$35,"<>") -> 2
B46: Energie & Umwelt | C46: =COUNTIFS($B$4:$B$35,$B46,C$4:C$35,"<>") -> 5 | D46: =COUNTIFS($B$4:$B$35,$B46,D$4:D$35,"<>") -> 2 | E46: =COUNTIFS($B$4:$B$35,$B46,E$4:E$35,"<>") -> 1 | F46: =COUNTIFS($B$4:$B$35,$B46,F$4:F$35,"<>") -> 0 | G46: =COUNTIFS($B$4:$B$35,$B46,G$4:G$35,"<>") -> 1 | H46: =COUNTIFS($B$4:$B$35,$B46,H$4:H$35,"<>") -> 1 | I46: =COUNTIFS($B$4:$B$35,$B46,I$4:I$35,"<>") -> 8 | J46: =COUNTIFS($B$4:$B$35,$B46,J$4:J$35,"<>") -> 1 | ... M46: =COUNTIFS($B$4:$B$35,$B46,M$4:M$35,"<>") -> 2
B47: Fertigungsprozesse und Materialien | C47: =COUNTIFS($B$4:$B$35,$B47,C$4:C$35,"<>") -> 7 | D47: =COUNTIFS($B$4:$B$35,$B47,D$4:D$35,"<>") -> 2 | E47: =COUNTIFS($B$4:$B$35,$B47,E$4:E$35,"<>") -> 4 | F47: =COUNTIFS($B$4:$B$35,$B47,F$4:F$35,"<>") -> 4 | G47: =COUNTIFS($B$4:$B$35,$B47,G$4:G$35,"<>") -> 3 | H47: =COUNTIFS($B$4:$B$35,$B47,H$4:H$35,"<>") -> 4 | I47: =COUNTIFS($B$4:$B$35,$B47,I$4:I$35,"<>") -> 5 | J47: =COUNTIFS($B$4:$B$35,$B47,J$4:J$35,"<>") -> 3 | ... M47: =COUNTIFS($B$4:$B$35,$B47,M$4:M$35,"<>") -> 1
B48: Life Sciences | C48: =COUNTIFS($B$4:$B$35,$B48,C$4:C$35,"<>") -> 5 | D48: =COUNTIFS($B$4:$B$35,$B48,D$4:D$35,"<>") -> 6 | E48: =COUNTIFS($B$4:$B$35,$B48,E$4:E$35,"<>") -> 2 | F48: =COUNTIFS($B$4:$B$35,$B48,F$4:F$35,"<>") -> 2 | G48: =COUNTIFS($B$4:$B$35,$B48,G$4:G$35,"<>") -> 2 | H48: =COUNTIFS($B$4:$B$35,$B48,H$4:H$35,"<>") -> 0 | I48: =COUNTIFS($B$4:$B$35,$B48,I$4:I$35,"<>") -> 3 | J48: =COUNTIFS($B$4:$B$35,$B48,J$4:J$35,"<>") -> 3 | ... M48: =COUNTIFS($B$4:$B$35,$B48,M$4:M$35,"<>") -> 0
B49: Space | C49: =COUNTIFS($B$4:$B$35,$B49,C$4:C$35,"<>") -> 0 | D49: =COUNTIFS($B$4:$B$35,$B49,D$4:D$35,"<>") -> 0 | E49: =COUNTIFS($B$4:$B$35,$B49,E$4:E$35,"<>") -> 0 | F49: =COUNTIFS($B$4:$B$35,$B49,F$4:F$35,"<>") -> 0 | G49: =COUNTIFS($B$4:$B$35,$B49,G$4:G$35,"<>") -> 1 | H49: =COUNTIFS($B$4:$B$35,$B49,H$4:H$35,"<>") -> 0 | I49: =COUNTIFS($B$4:$B$35,$B49,I$4:I$35,"<>") -> 1 | J49: =COUNTIFS($B$4:$B$35,$B49,J$4:J$35,"<>") -> 0 | ... M49: =COUNTIFS($B$4:$B$35,$B49,M$4:M$35,"<>") -> 0
...

Sheet h-index-alt
E1: Research-Gate | G1: Google Scholar
A2: TO-Begriff | B2: Institution | C2: Forschungsgruppe/Forschungsgruppenleiter | D2: Person/Gruppenleiter | E2: incl. Self-citations | F2: excl. Self-citations | G2: Alle | H2: Seit2015
A3: 3D-Biodruck | B3: ETH | C3: D-HEST, Tissue Engineering and Biofabrication; | D3: Marcy Zenobi-Wong | E3: 24 | F3: 21 | G3: 43 | H3: 33
A4: 3D-Biodruck | B4: ZHAW | C4: ICBT, 3D Tissues and Biofabrication | D4: Markus Rimann | E4: 20 | F4: 20 | G4: nv | H4: nv
A5: 3D-Biodruck | B5: Adolph Merkle Institute | C5: BioNanomaterials | D5: Barbara Rothen-Rutishauser | E5: nv | F5: nv | G5: nv | H5: nv
A6: 3D-Biodruck | B6: ZHAW | C6: ZHAW, ICBT, Metabolic Tissue Engineering | D6: Michael Raghunath | E6: 42 | F6: 40 | G6: 48 | H6: 29
A7: 5G | B7: ETH | D7: David Basin | E7: nv | F7: nv | G7: 57 | H7: 36
A8: 5G | B8: ETH | D8: Jürg Leuthold | E8: 62 | F8: 57 | G8: 73 | H8: 51
A9: 5G | B9: ETH | D9: Armin Wittneben | E9: nv | F9: nv | G9: nv | H9: nv
A10: 5G | B10: ETH | D10: Friedemann Mattern | E10: nv | F10: nv | G10: 49 | H10: 28
A11: 5G | B11: ETH | D11: Bastian Bergmann | E11: nv | F11: nv | G11: nv | H11: nv
A12: 5G | B12: EPFL | D12: Jean-Pierre Hubaux | E12: 58 | F12: 57 | G12: 86 | H12: 58
A13: 5G | B13: EPFL | D13: Anja Skrivervik | E13: nv | F13: nv | G13: 32 | H13: 23
A14: 5G | B14: EPFL | D14: Andreas Burg | E14: 35 | F14: 34 | G14: 41 | H14: 30
A15: 5G | B15: EPFL | D15: Alcherio Martinoli | E15: nv | F15: nv | G15: 47 | H15: 31
A16: Additive Fertigung | B16: Inspire | D16: Spierings/Schmid | E16: 17 | F16: 17 | G16: nv | H16: nv
A17: Additive Fertigung | B17: ETH | D17: Konrad Wegener | E17: 31 | F17: 30 | G17: nv | H17: nv
A18: Additive Fertigung | B18: ETH | D18: Mirko Meboldt | E18: 15 | F18: 13 | G18: 18 | H18: 18
A19: Additive Fertigung | C19: Engineering Design and Computing | D19: Kristina Shea | E19: nv | F19: nv | G19: 34 | H19: 25
A20: Additive Fertigung | B20: EPFL | D20: Roland Logé | E20: 26 | F20: 26 | G20: 29 | H20: 23
A21: Additive Fertigung | B21: FHNW | D21: Erik Schkommodau | E21: 11 | F21: 11 | G21: nv | H21: nv
A22: Additive Fertigung | B22: FHNW | D22: Daniel Seiler | E22: nv | F22: nv | G22: nv | H22: nv
A23: Additive Fertigung | B23: SUPSI | D23: Anna Valente | E23: nv | F23: nv | G23: nv | H23: nv
A24: Additive Fertigung | B24: EMPA | D24: Kilian Wasmer | E24: 18 | F24: 16 | G24: nv | H24: nv
A25: Additive Fertigung | B25: Heia-Fr | D25: Fritz Bircher | E25: nv | F25: nv | G25: nv | H25: nv | I25: Andere Personen da
A26: Additive Fertigung | B26: ZHAW | D26: Andreas Kirchheim | E26: 3 | F26: 3 | G26: nv | H26: nv
A27: Additive Fertigung | B27: HEFR | C27: HEFR
A28: Additive Fertigung | B28: HSR | C28: HSR
A29: Additive Fertigung | B29: HSLU | C29: HSLU
A30: Additive Fertigung | B30: BFH | C30: BFH
A31: Additive Fertigung | B31: CSEM | C31: CSEM
A32: Additive Fertigung | B32: FHO | C32: FHO | D32: Mohammad Rabiey | E32: 11 | F32: 11 | G32: nv | H32: nv
A33: Additive Fertigung | B33: FHO | D33: Frank Ehrig | E33: nv | F33: nv | G33: nv | H33: nv
A34: Alternative Antriebssysteme - technisch | B34: ETH | C34: Laboratorium für Aerothermochemie und Verbrennungssysteme | D34: Konstantinos Boulouchos | E34: 12 | F34: 12 | G34: nv | H34: nv
A35: Alternative Antriebssysteme - technisch | B35: ETH | C35: Insitut für Dynamische Systeme und Regelungstechnik | D35: Onder | E35: 20 | F35: 19 | G35: nv | H35: nv
A36: Alternative Antriebssysteme - technisch | B36: PSI | C36: Labor für Elektrochemie | D36: Büchi | E36: 37 | F36: 35 | G36: 44 | H36: 30
A37: Alternative Antriebssysteme - technisch | B37: ZHAW | C37: Institute of Computational Physics | D37: Schumacher | E37: nv | F37: nv | G37: nv | H37: nv
A38: Alternative Antriebssysteme - technisch | B38: BFH | C38: Zentrums für Energiespeicherung | D38: Vezzini | E38: 8 | F38: 8 | G38: 10 | H38: 7
A39: Alternative Antriebssysteme - technisch | B39: FHNW | C39: Thermoengineering | D39: Hermann | E39: 8 | F39: 7 | G39: nv | H39: nv
A40: Alternative Antriebssysteme - technisch | B40: EMPA | C40: Fahrzeugantriebssysteme | D40: Christian Bach | E40: 10 | F40: 10 | G40: nv | H40: nv
...

Sheet überblick-alt
B1: Forschungsgruppen | D1: Mittelwert H-Index | H1: Mtlwrt H-Index (beide Werte) | J1: Ohne Werte
B2: Anzahl | C2: Personen | D2: RG | E2: RG (ohne) | F2: GS | G2: GS seit 15 | H2: RG | I2: GS | J2: RG nv | K2: GS nv | L2: beide nv
A3: 3D-Biodruck | C3: =COUNTIFS('h-index-alt'!A:A,'überblick-alt'!A3) -> 4 | D3: =IFERROR(SUMIFS('h-index-alt'!$E$3:$E$463,'h-index-alt'!$A$3:$A$463,A3)/COUNTIFS('h-index-alt'!$E$3:$E$463,"<>nv",'h-index-alt'!$E$3:$E$463,"<>",'h-index-alt'!$A$3:$A$463,'überblick-alt'!A3),"") -> 28.666667 | E3: =SUMIFS('h-index-alt'!F$3:F$463,'h-index-alt'!$A$3:$A$463,'überblick-alt'!$A3)/COUNTIFS('h-index-alt'!$A$3:$A$463,'überblick-alt'!$A3) -> 20.25 | F3: =SUMIFS('h-index-alt'!G$3:G$463,'h-index-alt'!$A$3:$A$463,'überblick-alt'!$A3)/COUNTIFS('h-index-alt'!$A$3:$A$463,'überblick-alt'!$A3) -> 22.75 | G3: =IFERROR(SUMIFS('h-index-alt'!$H$3:$H$463,'h-index-alt'!$A$3:$A$463,A3)/COUNTIFS('h-index-alt'!$H$3:$H$463,"<>nv",'h-index-alt'!$H$3:$H$463,"<>",'h-index-alt'!$A$3:$A$463,'überblick-alt'!A3),"") -> 31 | H3: =IFERROR(SUMIFS('h-index-alt'!$E$3:$E$463,'h-index-alt'!$A$3:$A$463,A3,'h-index-alt'!$H$3:$H$463,"<>nv")/COUNTIFS('h-index-alt'!$E$3:$E$463,"<>nv",'h-index-alt'!$E$3:$E$463,"<>",'h-index-alt'!$A$3:$A$463,'überblick-alt'!A3,'h-index-alt'!$H$3:$H$463,"<>nv"),"") -> 33 | I3: =IFERROR(SUMIFS('h-index-alt'!$H$3:$H$463,'h-index-alt'!$A$3:$A$463,A3,'h-index-alt'!$E$3:$E$463,"<>nv")/COUNTIFS('h-index-alt'!$H$3:$H$463,"<>nv",'h-index-alt'!$H$3:$H$463,"<>",'h-index-alt'!$A$3:$A$463,'überblick-alt'!A3,'h-index-alt'!$E$3:$E$463,"<>nv"),"") -> 31 | J3: =COUNTIFS('h-index-alt'!A:A,'überblick-alt'!A3,'h-index-alt'!E:E,"nv") -> 1 | K3: =COUNTIFS('h-index-alt'!A:A,'überblick-alt'!A3,'h-index-alt'!G:G,"nv") -> 2 | L3: =COUNTIFS('h-index-alt'!A:A,'überblick-alt'!A3,'h-index-alt'!G:G,"nv",'h-index-alt'!E:E,"nv") -> 1
A4: 5G | C4: =COUNTIFS('h-index-alt'!A:A,'überblick-alt'!A4) -> 9 | D4: =IFERROR(SUMIFS('h-index-alt'!$E$3:$E$463,'h-index-alt'!$A$3:$A$463,A4)/COUNTIFS('h-index-alt'!$E$3:$E$463,"<>nv",'h-index-alt'!$E$3:$E$463,"<>",'h-index-alt'!$A$3:$A$463,'überblick-alt'!A4),"") -> 51.666667 | E4: =SUMIFS('h-index-alt'!F$3:F$463,'h-index-alt'!$A$3:$A$463,'überblick-alt'!$A4)/COUNTIFS('h-index-alt'!$A$3:$A$463,'überblick-alt'!$A4) -> 16.444444 | F4: =SUMIFS('h-index-alt'!G$3:G$463,'h-index-alt'!$A$3:$A$463,'überblick-alt'!$A4)/COUNTIFS('h-index-alt'!$A$3:$A$463,'überblick-alt'!$A4) -> 42.777778 | G4: =IFERROR(SUMIFS('h-index-alt'!$H$3:$H$463,'h-index-alt'!$A$3:$A$463,A4)/COUNTIFS('h-index-alt'!$H$3:$H$463,"<>nv",'h-index-alt'!$H$3:$H$463,"<>",'h-index-alt'!$A$3:$A$463,'überblick-alt'!A4),"") -> 36.714286 | H4: =IFERROR(SUMIFS('h-index-alt'!$E$3:$E$463,'h-index-alt'!$A$3:$A$463,A4,'h-index-alt'!$H$3:$H$463,"<>nv")/COUNTIFS('h-index-alt'!$E$3:$E$463,"<>nv",'h-index-alt'!$E$3:$E$463,"<>",'h-index-alt'!$A$3:$A$463,'überblick-alt'!A4,'h-index-alt'!$H$3:$H$463,"<>nv"),"") -> 51.666667 | I4: =IFERROR(SUMIFS('h-index-alt'!$H$3:$H$463,'h-index-alt'!$A$3:$A$463,A4,'h-index-alt'!$E$3:$E$463,"<>nv")/COUNTIFS('h-index-alt'!$H$3:$H$463,"<>nv",'h-index-alt'!$H$3:$H$463,"<>",'h-index-alt'!$A$3:$A$463,'überblick-alt'!A4,'h-index-alt'!$E$3:$E$463,"<>nv"),"") -> 46.333333 | J4: =COUNTIFS('h-index-alt'!A:A,'überblick-alt'!A4,'h-index-alt'!E:E,"nv") -> 6 | K4: =COUNTIFS('h-index-alt'!A:A,'überblick-alt'!A4,'h-index-alt'!G:G,"nv") -> 2 | L4: =COUNTIFS('h-index-alt'!A:A,'überblick-alt'!A4,'h-index-alt'!G:G,"nv",'h-index-alt'!E:E,"nv") -> 2
A5: Additive Fertigung | C5: =COUNTIFS('h-index-alt'!A:A,'überblick-alt'!A5) -> 18 | D5: =IFERROR(SUMIFS('h-index-alt'!$E$3:$E$463,'h-index-alt'!$A$3:$A$463,A5)/COUNTIFS('h-index-alt'!$E$3:$E$463,"<>nv",'h-index-alt'!$E$3:$E$463,"<>",'h-index-alt'!$A$3:$A$463,'überblick-alt'!A5),"") -> 16.5 | E5: =SUMIFS('h-index-alt'!F$3:F$463,'h-index-alt'!$A$3:$A$463,'überblick-alt'!$A5)/COUNTIFS('h-index-alt'!$A$3:$A$463,'überblick-alt'!$A5) -> 7.0555556 | F5: =SUMIFS('h-index-alt'!G$3:G$463,'h-index-alt'!$A$3:$A$463,'überblick-alt'!$A5)/COUNTIFS('h-index-alt'!$A$3:$A$463,'überblick-alt'!$A5) -> 4.5 | G5: =IFERROR(SUMIFS('h-index-alt'!$H$3:$H$463,'h-index-alt'!$A$3:$A$463,A5)/COUNTIFS('h-index-alt'!$H$3:$H$463,"<>nv",'h-index-alt'!$H$3:$H$463,"<>",'h-index-alt'!$A$3:$A$463,'überblick-alt'!A5),"") -> 22 | H5: =IFERROR(SUMIFS('h-index-alt'!$E$3:$E$463,'h-index-alt'!$A$3:$A$463,A5,'h-index-alt'!$H$3:$H$463,"<>nv")/COUNTIFS('h-index-alt'!$E$3:$E$463,"<>nv",'h-index-alt'!$E$3:$E$463,"<>",'h-index-alt'!$A$3:$A$463,'überblick-alt'!A5,'h-index-alt'!$H$3:$H$463,"<>nv"),"") -> 20.5 | I5: =IFERROR(SUMIFS('h-index-alt'!$H$3:$H$463,'h-index-alt'!$A$3:$A$463,A5,'h-index-alt'!$E$3:$E$463,"<>nv")/COUNTIFS('h-index-alt'!$H$3:$H$463,"<>nv",'h-index-alt'!$H$3:$H$463,"<>",'h-index-alt'!$A$3:$A$463,'überblick-alt'!A5,'h-index-alt'!$E$3:$E$463,"<>nv"),"") -> 20.5 | J5: =COUNTIFS('h-index-alt'!A:A,'überblick-alt'!A5,'h-index-alt'!E:E,"nv") -> 5 | K5: =COUNTIFS('h-index-alt'!A:A,'überblick-alt'!A5,'h-index-alt'!G:G,"nv") -> 10 | L5: =COUNTIFS('h-index-alt'!A:A,'überblick-alt'!A5,'h-index-alt'!G:G,"nv",'h-index-alt'!E:E,"nv") -> 4
A6: Alternative Antriebssysteme - technisch | C6: =COUNTIFS('h-index-alt'!A:A,'überblick-alt'!A6) -> 7 | D6: =IFERROR(SUMIFS('h-index-alt'!$E$3:$E$463,'h-index-alt'!$A$3:$A$463,A6)/COUNTIFS('h-index-alt'!$E$3:$E$463,"<>nv",'h-index-alt'!$E$3:$E$463,"<>",'h-index-alt'!$A$3:$A$463,'überblick-alt'!A6),"") -> 15.833333 | E6: =SUMIFS('h-index-alt'!F$3:F$463,'h-index-alt'!$A$3:$A$463,'überblick-alt'!$A6)/COUNTIFS('h-index-alt'!$A$3:$A$463,'überblick-alt'!$A6) -> 13 | F6: =SUMIFS('h-index-alt'!G$3:G$463,'h-index-alt'!$A$3:$A$463,'überblick-alt'!$A6)/COUNTIFS('h-index-alt'!$A$3:$A$463,'überblick-alt'!$A6) -> 7.7142857 | G6: =IFERROR(SUMIFS('h-index-alt'!$H$3:$H$463,'h-index-alt'!$A$3:$A$463,A6)/COUNTIFS('h-index-alt'!$H$3:$H$463,"<>nv",'h-index-alt'!$H$3:$H$463,"<>",'h-index-alt'!$A$3:$A$463,'überblick-alt'!A6),"") -> 18.5 | H6: =IFERROR(SUMIFS('h-index-alt'!$E$3:$E$463,'h-index-alt'!$A$3:$A$463,A6,'h-index-alt'!$H$3:$H$463,"<>nv")/COUNTIFS('h-index-alt'!$E$3:$E$463,"<>nv",'h-index-alt'!$E$3:$E$463,"<>",'h-index-alt'!$A$3:$A$463,'überblick-alt'!A6,'h-index-alt'!$H$3:$H$463,"<>nv"),"") -> 22.5 | I6: =IFERROR(SUMIFS('h-index-alt'!$H$3:$H$463,'h-index-alt'!$A$3:$A$463,A6,'h-index-alt'!$E$3:$E$463,"<>nv")/COUNTIFS('h-index-alt'!$H$3:$H$463,"<>nv",'h-index-alt'!$H$3:$H$463,"<>",'h-index-alt'!$A$3:$A$463,'überblick-alt'!A6,'h-index-alt'!$E$3:$E$463,"<>nv"),"") -> 18.5 | J6: =COUNTIFS('h-index-alt'!A:A,'überblick-alt'!A6,'h-index-alt'!E:E,"nv") -> 1 | K6: =COUNTIFS('h-index-alt'!A:A,'überblick-alt'!A6,'h-index-alt'!G:G,"nv") -> 5 | L6: =COUNTIFS('h-index-alt'!A:A,'überblick-alt'!A6,'h-index-alt'!G:G,"nv",'h-index-alt'!E:E,"nv") -> 1
A7: Alternative Antriebssysteme - nicht technisch | C7: =COUNTIFS('h-index-alt'!A:A,'überblick-alt'!A7) -> 3 | D7: =IFERROR(SUMIFS('h-index-alt'!$E$3:$E$463,'h-index-alt'!$A$3:$A$463,A7)/COUNTIFS('h-index-alt'!$E$3:$E$463,"<>nv",'h-index-alt'!$E$3:$E$463,"<>",'h-index-alt'!$A$3:$A$463,'überblick-alt'!A7),"") -> 26 | E7: =SUMIFS('h-index-alt'!F$3:F$463,'h-index-alt'!$A$3:$A$463,'überblick-alt'!$A7)/COUNTIFS('h-index-alt'!$A$3:$A$463,'überblick-alt'!$A7) -> 25 | F7: =SUMIFS('h-index-alt'!G$3:G$463,'h-index-alt'!$A$3:$A$463,'überblick-alt'!$A7)/COUNTIFS('h-index-alt'!$A$3:$A$463,'überblick-alt'!$A7) -> 28 | G7: =IFERROR(SUMIFS('h-index-alt'!$H$3:$H$463,'h-index-alt'!$A$3:$A$463,A7)/COUNTIFS('h-index-alt'!$H$3:$H$463,"<>nv",'h-index-alt'!$H$3:$H$463,"<>",'h-index-alt'!$A$3:$A$463,'überblick-alt'!A7),"") -> 31.5 | H7: =IFERROR(SUMIFS('h-index-alt'!$E$3:$E$463,'h-index-alt'!$A$3:$A$463,A7,'h-index-alt'!$H$3:$H$463,"<>nv")/COUNTIFS('h-index-alt'!$E$3:$E$463,"<>nv",'h-index-alt'!$E$3:$E$463,"<>",'h-index-alt'!$A$3:$A$463,'überblick-alt'!A7,'h-index-alt'!$H$3:$H$463,"<>nv"),"") -> 31 | I7: =IFERROR(SUMIFS('h-index-alt'!$H$3:$H$463,'h-index-alt'!$A$3:$A$463,A7,'h-index-alt'!$E$3:$E$463,"<>nv")/COUNTIFS('h-index-alt'!$H$3:$H$463,"<>nv",'h-index-alt'!$H$3:$H$463,"<>",'h-index-alt'!$A$3:$A$463,'überblick-alt'!A7,'h-index-alt'!$E$3:$E$463,"<>nv"),"") -> 31.5 | J7: =COUNTIFS('h-index-alt'!A:A,'überblick-alt'!A7,'h-index-alt'!E:E,"nv") -> 0 | K7: =COUNTIFS('h-index-alt'!A:A,'überblick-alt'!A7,'h-index-alt'!G:G,"nv") -> 1 | L7: =COUNTIFS('h-index-alt'!A:A,'überblick-alt'!A7,'h-index-alt'!G:G,"nv",'h-index-alt'!E:E,"nv") -> 0
A8: Alternative Antriebssysteme | C8: =COUNTIFS('h-index-alt'!A:A,'überblick-alt'!A8) -> 3 | D8: =IFERROR(SUMIFS('h-index-alt'!$E$3:$E$463,'h-index-alt'!$A$3:$A$463,A8)/COUNTIFS('h-index-alt'!$E$3:$E$463,"<>nv",'h-index-alt'!$E$3:$E$463,"<>",'h-index-alt'!$A$3:$A$463,'überblick-alt'!A8),"") -> 20 | E8: =SUMIFS('h-index-alt'!F$3:F$463,'h-index-alt'!$A$3:$A$463,'überblick-alt'!$A8)/COUNTIFS('h-index-alt'!$A$3:$A$463,'überblick-alt'!$A8) -> 12.666667 | F8: =SUMIFS('h-index-alt'!G$3:G$463,'h-index-alt'!$A$3:$A$463,'überblick-alt'!$A8)/COUNTIFS('h-index-alt'!$A$3:$A$463,'überblick-alt'!$A8) -> 14 | G8: =IFERROR(SUMIFS('h-index-alt'!$H$3:$H$463,'h-index-alt'!$A$3:$A$463,A8)/COUNTIFS('h-index-alt'!$H$3:$H$463,"<>nv",'h-index-alt'!$H$3:$H$463,"<>",'h-index-alt'!$A$3:$A$463,'überblick-alt'!A8),"") -> 25 | H8: =IFERROR(SUMIFS('h-index-alt'!$E$3:$E$463,'h-index-alt'!$A$3:$A$463,A8,'h-index-alt'!$H$3:$H$463,"<>nv")/COUNTIFS('h-index-alt'!$E$3:$E$463,"<>nv",'h-index-alt'!$E$3:$E$463,"<>",'h-index-alt'!$A$3:$A$463,'überblick-alt'!A8,'h-index-alt'!$H$3:$H$463,"<>nv"),"") -> 36 | I8: =IFERROR(SUMIFS('h-index-alt'!$H$3:$H$463,'h-index-alt'!$A$3:$A$463,A8,'h-index-alt'!$E$3:$E$463,"<>nv")/COUNTIFS('h-index-alt'!$H$3:$H$463,"<>nv",'h-index-alt'!$H$3:$H$463,"<>",'h-index-alt'!$A$3:$A$463,'überblick-alt'!A8,'h-index-alt'!$E$3:$E$463,"<>nv"),"") -> 25 | J8: =COUNTIFS('h-index-alt'!A:A,'überblick-alt'!A8,'h-index-alt'!E:E,"nv") -> 1 | K8: =COUNTIFS('h-index-alt'!A:A,'überblick-alt'!A8,'h-index-alt'!G:G,"nv") -> 2 | L8: =COUNTIFS('h-index-alt'!A:A,'überblick-alt'!A8,'h-index-alt'!G:G,"nv",'h-index-alt'!E:E,"nv") -> 1
A9: Alternative Proteinquellen | C9: =COUNTIFS('h-index-alt'!A:A,'überblick-alt'!A9) -> 19 | D9: =IFERROR(SUMIFS('h-index-alt'!$E$3:$E$463,'h-index-alt'!$A$3:$A$463,A9)/COUNTIFS('h-index-alt'!$E$3:$E$463,"<>nv",'h-index-alt'!$E$3:$E$463,"<>",'h-index-alt'!$A$3:$A$463,'überblick-alt'!A9),"") -> 29.111111 | E9: =SUMIFS('h-index-alt'!F$3:F$463,'h-index-alt'!$A$3:$A$463,'überblick-alt'!$A9)/COUNTIFS('h-index-alt'!$A$3:$A$463,'überblick-alt'!$A9) -> 25.947368 | F9: =SUMIFS('h-index-alt'!G$3:G$463,'h-index-alt'!$A$3:$A$463,'überblick-alt'!$A9)/COUNTIFS('h-index-alt'!$A$3:$A$463,'überblick-alt'!$A9) -> 22.157895 | G9: =IFERROR(SUMIFS('h-index-alt'!$H$3:$H$463,'h-index-alt'!$A$3:$A$463,A9)/COUNTIFS('h-index-alt'!$H$3:$H$463,"<>nv",'h-index-alt'!$H$3:$H$463,"<>",'h-index-alt'!$A$3:$A$463,'überblick-alt'!A9),"") -> 33 | H9: =IFERROR(SUMIFS('h-index-alt'!$E$3:$E$463,'h-index-alt'!$A$3:$A$463,A9,'h-index-alt'!$H$3:$H$463,"<>nv")/COUNTIFS('h-index-alt'!$E$3:$E$463,"<>nv",'h-index-alt'!$E$3:$E$463,"<>",'h-index-alt'!$A$3:$A$463,'überblick-alt'!A9,'h-index-alt'!$H$3:$H$463,"<>nv"),"") -> 36.6 | I9: =IFERROR(SUMIFS('h-index-alt'!$H$3:$H$463,'h-index-alt'!$A$3:$A$463,A9,'h-index-alt'!$E$3:$E$463,"<>nv")/COUNTIFS('h-index-alt'!$H$3:$H$463,"<>nv",'h-index-alt'!$H$3:$H$463,"<>",'h-index-alt'!$A$3:$A$463,'überblick-alt'!A9,'h-index-alt'!$E$3:$E$463,"<>nv"),"") -> 33 | J9: =COUNTIFS('h-index-alt'!A:A,'überblick-alt'!A9,'h-index-alt'!E:E,"nv") -> 1 | K9: =COUNTIFS('h-index-alt'!A:A,'überblick-alt'!A9,'h-index-alt'!G:G,"nv") -> 9 | L9: =COUNTIFS('h-index-alt'!A:A,'überblick-alt'!A9,'h-index-alt'!G:G,"nv",'h-index-alt'!E:E,"nv") -> 1
A10: Analyse von Big Data | C10: =COUNTIFS('h-index-alt'!A:A,'überblick-alt'!A10) -> 1 | D10: =IFERROR(SUMIFS('h-index-alt'!$E$3:$E$463,'h-index-alt'!$A$3:$A$463,A10)/COUNTIFS('h-index-alt'!$E$3:$E$463,"<>nv",'h-index-alt'!$E$3:$E$463,"<>",'h-index-alt'!$A$3:$A$463,'überblick-alt'!A10),"") | E10: =SUMIFS('h-index-alt'!F$3:F$463,'h-index-alt'!$A$3:$A$463,'überblick-alt'!$A10)/COUNTIFS('h-index-alt'!$A$3:$A$463,'überblick-alt'!$A10) -> 0 | F10: =SUMIFS('h-index-alt'!G$3:G$463,'h-index-alt'!$A$3:$A$463,'überblick-alt'!$A10)/COUNTIFS('h-index-alt'!$A$3:$A$463,'überblick-alt'!$A10) -> 0 | G10: =IFERROR(SUMIFS('h-index-alt'!$H$3:$H$463,'h-index-alt'!$A$3:$A$463,A10)/COUNTIFS('h-index-alt'!$H$3:$H$463,"<>nv",'h-index-alt'!$H$3:$H$463,"<>",'h-index-alt'!$A$3:$A$463,'überblick-alt'!A10),"") | H10: =IFERROR(SUMIFS('h-index-alt'!$E$3:$E$463,'h-index-alt'!$A$3:$A$463,A10,'h-index-alt'!$H$3:$H$463,"<>nv")/COUNTIFS('h-index-alt'!$E$3:$E$463,"<>nv",'h-index-alt'!$E$3:$E$463,"<>",'h-index-alt'!$A$3:$A$463,'überblick-alt'!A10,'h-index-alt'!$H$3:$H$463,"<>nv"),"") | I10: =IFERROR(SUMIFS('h-index-alt'!$H$3:$H$463,'h-index-alt'!$A$3:$A$463,A10,'h-index-alt'!$E$3:$E$463,"<>nv")/COUNTIFS('h-index-alt'!$H$3:$H$463,"<>nv",'h-index-alt'!$H$3:$H$463,"<>",'h-index-alt'!$A$3:$A$463,'überblick-alt'!A10,'h-index-alt'!$E$3:$E$463,"<>nv"),"") | J10: =COUNTIFS('h-index-alt'!A:A,'überblick-alt'!A10,'h-index-alt'!E:E,"nv") -> 0 | K10: =COUNTIFS('h-index-alt'!A:A,'überblick-alt'!A10,'h-index-alt'!G:G,"nv") -> 0 | L10: =COUNTIFS('h-index-alt'!A:A,'überblick-alt'!A10,'h-index-alt'!G:G,"nv",'h-index-alt'!E:E,"nv") -> 0
A11: Antimikrobielle Polymere | C11: =COUNTIFS('h-index-alt'!A:A,'überblick-alt'!A11) -> 2 | D11: =IFERROR(SUMIFS('h-index-alt'!$E$3:$E$463,'h-index-alt'!$A$3:$A$463,A11)/COUNTIFS('h-index-alt'!$E$3:$E$463,"<>nv",'h-index-alt'!$E$3:$E$463,"<>",'h-index-alt'!$A$3:$A$463,'überblick-alt'!A11),"") | E11: =SUMIFS('h-index-alt'!F$3:F$463,'h-index-alt'!$A$3:$A$463,'überblick-alt'!$A11)/COUNTIFS('h-index-alt'!$A$3:$A$463,'überblick-alt'!$A11) -> 0 | F11: =SUMIFS('h-index-alt'!G$3:G$463,'h-index-alt'!$A$3:$A$463,'überblick-alt'!$A11)/COUNTIFS('h-index-alt'!$A$3:$A$463,'überblick-alt'!$A11) -> 0 | G11: =IFERROR(SUMIFS('h-index-alt'!$H$3:$H$463,'h-index-alt'!$A$3:$A$463,A11)/COUNTIFS('h-index-alt'!$H$3:$H$463,"<>nv",'h-index-alt'!$H$3:$H$463,"<>",'h-index-alt'!$A$3:$A$463,'überblick-alt'!A11),"") | H11: =IFERROR(SUMIFS('h-index-alt'!$E$3:$E$463,'h-index-alt'!$A$3:$A$463,A11,'h-index-alt'!$H$3:$H$463,"<>nv")/COUNTIFS('h-index-alt'!$E$3:$E$463,"<>nv",'h-index-alt'!$E$3:$E$463,"<>",'h-index-alt'!$A$3:$A$463,'überblick-alt'!A11,'h-index-alt'!$H$3:$H$463,"<>nv"),"") | I11: =IFERROR(SUMIFS('h-index-alt'!$H$3:$H$463,'h-index-alt'!$A$3:$A$463,A11,'h-index-alt'!$E$3:$E$463,"<>nv")/COUNTIFS('h-index-alt'!$H$3:$H$463,"<>nv",'h-index-alt'!$H$3:$H$463,"<>",'h-index-alt'!$A$3:$A$463,'überblick-alt'!A11,'h-index-alt'!$E$3:$E$463,"<>nv"),"") | J11: =COUNTIFS('h-index-alt'!A:A,'überblick-alt'!A11,'h-index-alt'!E:E,"nv") -> 0 | K11: =COUNTIFS('h-index-alt'!A:A,'überblick-alt'!A11,'h-index-alt'!G:G,"nv") -> 0 | L11: =COUNTIFS('h-index-alt'!A:A,'überblick-alt'!A11,'h-index-alt'!G:G,"nv",'h-index-alt'!E:E,"nv") -> 0
A12: Augmented Reality | C12: =COUNTIFS('h-index-alt'!A:A,'überblick-alt'!A12) -> 5 | D12: =IFERROR(SUMIFS('h-index-alt'!$E$3:$E$463,'h-index-alt'!$A$3:$A$463,A12)/COUNTIFS('h-index-alt'!$E$3:$E$463,"<>nv",'h-index-alt'!$E$3:$E$463,"<>",'h-index-alt'!$A$3:$A$463,'überblick-alt'!A12),"") -> 12.333333 | E12: =SUMIFS('h-index-alt'!F$3:F$463,'h-index-alt'!$A$3:$A$463,'überblick-alt'!$A12)/COUNTIFS('h-index-alt'!$A$3:$A$463,'überblick-alt'!$A12) -> 6.4 | F12: =SUMIFS('h-index-alt'!G$3:G$463,'h-index-alt'!$A$3:$A$463,'überblick-alt'!$A12)/COUNTIFS('h-index-alt'!$A$3:$A$463,'überblick-alt'!$A12) -> 7.6 | G12: =IFERROR(SUMIFS('h-index-alt'!$H$3:$H$463,'h-index-alt'!$A$3:$A$463,A12)/COUNTIFS('h-index-alt'!$H$3:$H$463,"<>nv",'h-index-alt'!$H$3:$H$463,"<>",'h-index-alt'!$A$3:$A$463,'überblick-alt'!A12),"") -> 16.5 | H12: =IFERROR(SUMIFS('h-index-alt'!$E$3:$E$463,'h-index-alt'!$A$3:$A$463,A12,'h-index-alt'!$H$3:$H$463,"<>nv")/COUNTIFS('h-index-alt'!$E$3:$E$463,"<>nv",'h-index-alt'!$E$3:$E$463,"<>",'h-index-alt'!$A$3:$A$463,'überblick-alt'!A12,'h-index-alt'!$H$3:$H$463,"<>nv"),"") -> 16.5 | I12: =IFERROR(SUMIFS('h-index-alt'!$H$3:$H$463,'h-index-alt'!$A$3:$A$463,A12,'h-index-alt'!$E$3:$E$463,"<>nv")/COUNTIFS('h-index-alt'!$H$3:$H$463,"<>nv",'h-index-alt'!$H$3:$H$463,"<>",'h-index-alt'!$A$3:$A$463,'überblick-alt'!A12,'h-index-alt'!$E$3:$E$463,"<>nv"),"") -> 16.5 | J12: =COUNTIFS('h-index-alt'!A:A,'überblick-alt'!A12,'h-index-alt'!E:E,"nv") -> 2 | K12: =COUNTIFS('h-index-alt'!A:A,'überblick-alt'!A12,'h-index-alt'!G:G,"nv") -> 3 | L12: =COUNTIFS('h-index-alt'!A:A,'überblick-alt'!A12,'h-index-alt'!G:G,"nv",'h-index-alt'!E:E,"nv") -> 2
A13: Biokatalyse und Biosynthese | C13: =COUNTIFS('h-index-alt'!A:A,'überblick-alt'!A13) -> 11 | D13: =IFERROR(SUMIFS('h-index-alt'!$E$3:$E$463,'h-index-alt'!$A$3:$A$463,A13)/COUNTIFS('h-index-alt'!$E$3:$E$463,"<>nv",'h-index-alt'!$E$3:$E$463,"<>",'h-index-alt'!$A$3:$A$463,'überblick-alt'!A13),"") -> 20.333333 | E13: =SUMIFS('h-index-alt'!F$3:F$463,'h-index-alt'!$A$3:$A$463,'überblick-alt'!$A13)/COUNTIFS('h-index-alt'!$A$3:$A$463,'überblick-alt'!$A13) -> 10.363636 | F13: =SUMIFS('h-index-alt'!G$3:G$463,'h-index-alt'!$A$3:$A$463,'überblick-alt'!$A13)/COUNTIFS('h-index-alt'!$A$3:$A$463,'überblick-alt'!$A13) -> 12.636364 | G13: =IFERROR(SUMIFS('h-index-alt'!$H$3:$H$463,'h-index-alt'!$A$3:$A$463,A13)/COUNTIFS('h-index-alt'!$H$3:$H$463,"<>nv",'h-index-alt'!$H$3:$H$463,"<>",'h-index-alt'!$A$3:$A$463,'überblick-alt'!A13),"") -> 17 | H13: =IFERROR(SUMIFS('h-index-alt'!$E$3:$E$463,'h-index-alt'!$A$3:$A$463,A13,'h-index-alt'!$H$3:$H$463,"<>nv")/COUNTIFS('h-index-alt'!$E$3:$E$463,"<>nv",'h-index-alt'!$E$3:$E$463,"<>",'h-index-alt'!$A$3:$A$463,'überblick-alt'!A13,'h-index-alt'!$H$3:$H$463,"<>nv"),"") -> 21.5 | I13: =IFERROR(SUMIFS('h-index-alt'!$H$3:$H$463,'h-index-alt'!$A$3:$A$463,A13,'h-index-alt'!$E$3:$E$463,"<>nv")/COUNTIFS('h-index-alt'!$H$3:$H$463,"<>nv",'h-index-alt'!$H$3:$H$463,"<>",'h-index-alt'!$A$3:$A$463,'überblick-alt'!A13,'h-index-alt'!$E$3:$E$463,"<>nv"),"") -> 16.25 | J13: =COUNTIFS('h-index-alt'!A:A,'überblick-alt'!A13,'h-index-alt'!E:E,"nv") -> 5 | K13: =COUNTIFS('h-index-alt'!A:A,'überblick-alt'!A13,'h-index-alt'!G:G,"nv") -> 5 | L13: =COUNTIFS('h-index-alt'!A:A,'überblick-alt'!A13,'h-index-alt'!G:G,"nv",'h-index-alt'!E:E,"nv") -> 3
A14: Bioplastik | C14: =COUNTIFS('h-index-alt'!A:A,'überblick-alt'!A14) -> 5 | D14: =IFERROR(SUMIFS('h-index-alt'!$E$3:$E$463,'h-index-alt'!$A$3:$A$463,A14)/COUNTIFS('h-index-alt'!$E$3:$E$463,"<>nv",'h-index-alt'!$E$3:$E$463,"<>",'h-index-alt'!$A$3:$A$463,'überblick-alt'!A14),"") -> 20.5 | E14: =SUMIFS('h-index-alt'!F$3:F$463,'h-index-alt'!$A$3:$A$463,'überblick-alt'!$A14)/COUNTIFS('h-index-alt'!$A$3:$A$463,'überblick-alt'!$A14) -> 8 | F14: =SUMIFS('h-index-alt'!G$3:G$463,'h-index-alt'!$A$3:$A$463,'überblick-alt'!$A14)/COUNTIFS('h-index-alt'!$A$3:$A$463,'überblick-alt'!$A14) -> 15.2 | G14: =IFERROR(SUMIFS('h-index-alt'!$H$3:$H$463,'h-index-alt'!$A$3:$A$463,A14)/COUNTIFS('h-index-alt'!$H$3:$H$463,"<>nv",'h-index-alt'!$H$3:$H$463,"<>",'h-index-alt'!$A$3:$A$463,'überblick-alt'!A14),"") -> 18 | H14: =IFERROR(SUMIFS('h-index-alt'!$E$3:$E$463,'h-index-alt'!$A$3:$A$463,A14,'h-index-alt'!$H$3:$H$463,"<>nv")/COUNTIFS('h-index-alt'!$E$3:$E$463,"<>nv",'h-index-alt'!$E$3:$E$463,"<>",'h-index-alt'!$A$3:$A$463,'überblick-alt'!A14,'h-index-alt'!$H$3:$H$463,"<>nv"),"") -> 28 | I14: =IFERROR(SUMIFS('h-index-alt'!$H$3:$H$463,'h-index-alt'!$A$3:$A$463,A14,'h-index-alt'!$E$3:$E$463,"<>nv")/COUNTIFS('h-index-alt'!$H$3:$H$463,"<>nv",'h-index-alt'!$H$3:$H$463,"<>",'h-index-alt'!$A$3:$A$463,'überblick-alt'!A14,'h-index-alt'!$E$3:$E$463,"<>nv"),"") -> 23 | J14: =COUNTIFS('h-index-alt'!A:A,'überblick-alt'!A14,'h-index-alt'!E:E,"nv") -> 3 | K14: =COUNTIFS('h-index-alt'!A:A,'überblick-alt'!A14,'h-index-alt'!G:G,"nv") -> 2 | L14: =COUNTIFS('h-index-alt'!A:A,'überblick-alt'!A14,'h-index-alt'!G:G,"nv",'h-index-alt'!E:E,"nv") -> 1
... A47: Zukünftige Energiespeicherung | C47: =COUNTIFS('h-index-alt'!A:A,'überblick-alt'!A47) -> 26 | D47: =IFERROR(SUMIFS('h-index-alt'!$E$3:$E$463,'h-index-alt'!$A$3:$A$463,A47)/COUNTIFS('h-index-alt'!$E$3:$E$463,"<>nv",'h-index-alt'!$E$3:$E$463,"<>",'h-index-alt'!$A$3:$A$463,'überblick-alt'!A47),"") -> 35.8 | E47: =SUMIFS('h-index-alt'!F$3:F$463,'h-index-alt'!$A$3:$A$463,'überblick-alt'!$A47)/COUNTIFS('h-index-alt'!$A$3:$A$463,'überblick-alt'!$A47) -> 12.923077 | F47: =SUMIFS('h-index-alt'!G$3:G$463,'h-index-alt'!$A$3:$A$463,'überblick-alt'!$A47)/COUNTIFS('h-index-alt'!$A$3:$A$463,'überblick-alt'!$A47) -> 24.115385 | G47: =IFERROR(SUMIFS('h-index-alt'!$H$3:$H$463,'h-index-alt'!$A$3:$A$463,A47)/COUNTIFS('h-index-alt'!$H$3:$H$463,"<>nv",'h-index-alt'!$H$3:$H$463,"<>",'h-index-alt'!$A$3:$A$463,'überblick-alt'!A47),"") -> 37 | H47: =IFERROR(SUMIFS('h-index-alt'!$E$3:$E$463,'h-index-alt'!$A$3:$A$463,A47,'h-index-alt'!$H$3:$H$463,"<>nv")/COUNTIFS('h-index-alt'!$E$3:$E$463,"<>nv",'h-index-alt'!$E$3:$E$463,"<>",'h-index-alt'!$A$3:$A$463,'überblick-alt'!A47,'h-index-alt'!$H$3:$H$463,"<>nv"),"") -> 38.333333 | I47: =IFERROR(SUMIFS('h-index-alt'!$H$3:$H$463,'h-index-alt'!$A$3:$A$463,A47,'h-index-alt'!$E$3:$E$463,"<>nv")/COUNTIFS('h-index-alt'!$H$3:$H$463,"<>nv",'h-index-alt'!$H$3:$H$463,"<>",'h-index-alt'!$A$3:$A$463,'überblick-alt'!A47,'h-index-alt'!$E$3:$E$463,"<>nv"),"") -> 31.111111 | J47: =COUNTIFS('h-index-alt'!A:A,'überblick-alt'!A47,'h-index-alt'!E:E,"nv") -> 6 | K47: =COUNTIFS('h-index-alt'!A:A,'überblick-alt'!A47,'h-index-alt'!G:G,"nv") -> 4 | L47: =COUNTIFS('h-index-alt'!A:A,'überblick-alt'!A47,'h-index-alt'!G:G,"nv",'h-index-alt'!E:E,"nv") -> 3
A49: Mittelwert | D49: =SUMIF(D$3:D$47,">0")/COUNTIF(D$3:D$47,">0") -> 35.049878 | E49: =SUMIF(E$3:E$47,">0")/COUNTIF(E$3:E$47,">0") -> 19.902493 | F49: =SUMIF(F$3:F$47,">0")/COUNTIF(F$3:F$47,">0") -> 29.793642 | G49: =SUMIF(G$3:G$47,">0")/COUNTIF(G$3:G$47,">0") -> 35.722043 | H49: =SUMIF(H3:H47, "<>#DIV/0!")/COUNTIF(H3:H47,">0") -> 39.415747 | I49: =SUMIF(I3:I47, "<>#DIV/0!")/COUNTIF(I3:I47,">0") -> 35.945533 | J49: =SUM(J3:J47) -> 129 | K49: =SUM(K3:K47) -> 133 | L49: =SUM(L3:L47) -> 63
